Workbook

Sheet statements
B1: Financial Statements
A3: X | B3: Income Statement
B4: Figures in USD millions | D4: =D17 -> 2026 | E4: =E17 -> 2027 | F4: =F17 -> 2028 | G4: =G17 -> 2029 | H4: =H17 -> 2030
B5: Revenue | D5: =D63*D64 -> 198380 | E5: =E63*E64 -> 208299 | F5: =F63*F64 -> 223177.5 | G5: =G63*G64 -> 235576.25 | H5: =H63*H64 -> 247975
B6: COGS | D6: =-D66*D5 -> -85303.4 | E6: =-E66*E5 -> -89568.57 | F6: =-F66*F5 -> -89271 | G6: =-G66*G5 -> -89518.975 | H6: =-H66*H5 -> -94230.5
B7: Gross Profit | D7: =D5+D6 -> 113076.6 | E7: =E5+E6 -> 118730.43 | F7: =F5+F6 -> 133906.5 | G7: =G5+G6 -> 146057.27 | H7: =H5+H6 -> 153744.5
B8: SG&A | D8: =-D67*D5 -> -69433 | E8: =-E67*E5 -> -72904.65 | F8: =-F67*F5 -> -78112.125 | G8: =-G67*G5 -> -82451.688 | H8: =-H67*H5 -> -86791.25
B9: Depreciation | D9: =-D100 -> -6399 | E9: =-E100 -> -7599 | F9: =-F100 -> -8599 | G9: =-G100 -> -9349 | H9: =-H100 -> -10099
B10: Operating Profit | D10: =D7+D8+D9 -> 37244.6 | E10: =E7+E8+E9 -> 38226.78 | F10: =F7+F8+F9 -> 47195.375 | G10: =G7+G8+G9 -> 54256.587 | H10: =H7+H8+H9 -> 56854.25
B11: Interest | D11: =D130 -> 2800 | E11: =E130 -> 2800 | F11: =F130 -> 2800 | G11: =G130 -> 2800 | H11: =H130 -> 2800
B12: Earnings Before Tax | D12: =D10-D11 -> 34444.6 | E12: =E10-E11 -> 35426.78 | F12: =F10-F11 -> 44395.375 | G12: =G10-G11 -> 51456.587 | H12: =H10-H11 -> 54054.25
B13: Taxes | D13: =D69*D12 -> 7233.366 | E13: =E69*E12 -> 7439.6238 | F13: =F69*F12 -> 9323.0287 | G13: =G69*G12 -> 10805.883 | H13: =H69*H12 -> 11351.392
B14: Net Income | D14: =D12-D13 -> 27211.234 | E14: =E12-E13 -> 27987.156 | F14: =F12-F13 -> 35072.346 | G14: =G12-G13 -> 40650.704 | H14: =H12-H13 -> 42702.857
A16: X | B16: Balance Sheet
B17: Figures in USD | C17: 2025 | D17: =C17+1 -> 2026 | E17: =D17+1 -> 2027 | F17: =E17+1 -> 2028 | G17: =F17+1 -> 2029 | H17: =G17+1 -> 2030
B18: Cash & Cash Equivalents | C18: 14589 | D18: =D59 -> 21534.405 | E18: =E59 -> 32358.52 | F18: =F59 -> 50080.897 | G18: =G59 -> 71830.972 | H18: =H59 -> 91753.805 | I18: CFS
B19: Accounts Receivable | C19: 9877 | D19: =D5*D75 -> 12323.498 | E19: =E5*E75 -> 12939.673 | F19: =F5*F75 -> 13863.936 | G19: =G5*G75 -> 14634.154 | H19: =H5*H75 -> 15404.373
B20: Inventory | C20: 8579 | D20: =-D6*D76 -> 9643.2667 | E20: =-E6*E76 -> 10125.43 | F20: =-F6*F76 -> 10091.791 | G20: =-G6*G76 -> 10119.824 | H20: =-H6*H76 -> 10652.446
B21: Total Current Assets | C21: =SUM(C18:C20) -> 33045 | D21: =SUM(D18:D20) -> 43501.17 | E21: =SUM(E18:E20) -> 55423.623 | F21: =SUM(F18:F20) -> 74036.623 | G21: =SUM(G18:G20) -> 96584.949 | H21: =SUM(H18:H20) -> 117810.62
B22: Property Plant & Equipment (PPE) | C22: 48990 | D22: =D105 -> 57591 | E22: =E105 -> 61992 | F22: =F105 -> 63393 | G22: =G105 -> 61544 | H22: =H105 -> 58945 | I22: FA Schedule
B23: Total Assets | C23: =SUM(C21,C22) -> 82035 | D23: =SUM(D21,D22) -> 101092.17 | E23: =SUM(E21,E22) -> 117415.62 | F23: =SUM(F21,F22) -> 137429.62 | G23: =SUM(G21,G22) -> 158128.95 | H23: =SUM(H21,H22) -> 176755.62
B25: Accounts Payable | C25: 14880 | D25: =-D6*D77 -> 16725.936 | E25: =-E6*E77 -> 17562.233 | F25: =-F6*F77 -> 17503.887 | G25: =-G6*G77 -> 17552.509 | H25: =-H6*H77 -> 18476.325
B26: Revolver | C26: 0 | D26: =D126 -> 0 | E26: =E126 -> 0 | F26: =F126 -> 0 | G26: =G126 -> 0 | H26: =H126 -> 0 | I26: Revolver Schedule
B27: Total Current Liabilities | C27: =SUM(C25,C26) -> 14880 | D27: =SUM(D25,D26) -> 16725.936 | E27: =SUM(E25,E26) -> 17562.233 | F27: =SUM(F25,F26) -> 17503.887 | G27: =SUM(G25,G26) -> 17552.509 | H27: =SUM(H25,H26) -> 18476.325
B29: Long Term Debt | C29: 40000 | D29: =D79 -> 40000 | E29: =E79 -> 40000 | F29: =F79 -> 40000 | G29: =G79 -> 40000 | H29: =H79 -> 40000
B30: Total Liabilities | C30: =SUM(C27,C29) -> 54880 | D30: =SUM(D27,D29) -> 56725.936 | E30: =SUM(E27,E29) -> 57562.233 | F30: =SUM(F27,F29) -> 57503.887 | G30: =SUM(G27,G29) -> 57552.509 | H30: =SUM(H27,H29) -> 58476.325
B32: Common stock | C32: 25000 | D32: 25000 | E32: 25000 | F32: 25000 | G32: 25000 | H32: 25000 | I32: Share capital = No. of equity shares * Face Value per share
B33: Retained Earnings | C33: =24155-22000 -> 2155 | D33: =D111 -> 19366.234 | E33: =E111 -> 34853.39 | F33: =F111 -> 54925.736 | G33: =G111 -> 75576.441 | H33: =H111 -> 93279.298 | I33: RE Schedule
B34: Total Shareholders' Equity | C34: =SUM(C32:C33) -> 27155 | D34: =SUM(D32:D33) -> 44366.234 | E34: =SUM(E32:E33) -> 59853.39 | F34: =SUM(F32:F33) -> 79925.736 | G34: =SUM(G32:G33) -> 100576.44 | H34: =SUM(H32:H33) -> 118279.3
B36: Total Liabilities & Equity | C36: =SUM(C30,C34) -> 82035 | D36: =SUM(D30,D34) -> 101092.17 | E36: =SUM(E30,E34) -> 117415.62 | F36: =SUM(F30,F34) -> 137429.62 | G36: =SUM(G30,G34) -> 158128.95 | H36: =SUM(H30,H34) -> 176755.62
B38: Balance Sheet Check | C38: =C23-C36 -> 0 | D38: =D23-D36 -> 0 | E38: =E23-E36 -> 0 | F38: =F23-F36 -> 0 | G38: =G23-G36 -> 0 | H38: =H23-H36 -> 0
A40: X | B40: Cash Flow Statement
B41: Net Income | D41: =D14 -> 27211.234 | E41: =E14 -> 27987.156 | F41: =F14 -> 35072.346 | G41: =G14 -> 40650.704 | H41: =H14 -> 42702.857
B42: Depreciation | D42: =D100 -> 6399 | E42: =E100 -> 7599 | F42: =F100 -> 8599 | G42: =G100 -> 9349 | H42: =H100 -> 10099
B43: Change in Accounts Receivable | D43: =-D19+C19 -> -2446.4983 | E43: =-E19+D19 -> -616.17492 | F43: =-F19+E19 -> -924.26237 | G43: =-G19+F19 -> -770.21864 | H43: =-H19+G19 -> -770.21864
B44: Change in Inventory | D44: =-D20+C20 -> -1064.2667 | E44: =-E20+D20 -> -482.16334 | F44: =-F20+E20 -> 33.639303 | G44: =-G20+F20 -> -28.032752 | H44: =-H20+G20 -> -532.62229
B45: Change in Accounts Payable | D45: =D25-C25 -> 1845.9365 | E45: =E25-D25 -> 836.29682 | F45: =F25-E25 -> -58.34629 | G45: =G25-F25 -> 48.621908 | H45: =H25-G25 -> 923.81626
B46: Cash Flow from Operating Activities | D46: =SUM(D41:D45) -> 31945.405 | E46: =SUM(E41:E45) -> 35324.115 | F46: =SUM(F41:F45) -> 42722.377 | G46: =SUM(G41:G45) -> 49250.075 | H46: =SUM(H41:H45) -> 52422.833
B48: Capital Expenditures | D48: =-D85 -> -15000 | E48: =-E85 -> -12000 | F48: =-F85 -> -10000 | G48: =-G85 -> -7500 | H48: =-H85 -> -7500
B49: Cash Flow from Investing Activities | D49: =D48 -> -15000 | E49: =E48 -> -12000 | F49: =F48 -> -10000 | G49: =G48 -> -7500 | H49: =H48 -> -7500
...

Sheet Sensitivity Analysis
A1: NET INCOME SENSITIVITY ANALYSIS
A3: BASE NET INCOME | D3: =statements!H14 -> 42702.857
A5: Units Sold Sensitivity | C5: 37% | D5: 38% (Base) | E5: 39%
A6: 490 | B6: COGS % | C6: =statements!D135 -> 43564.819 | D6: =statements!E135 -> 41644.996 | E6: =statements!F135 -> 39725.174
A7: 500 (Base) | C7: =statements!D136 -> 44661.86 | D7: =statements!E136 -> 42702.857 | E7: =statements!F136 -> 40743.855
A8: 510 | C8: =statements!D137 -> 45758.901 | D8: =statements!E137 -> 43760.719 | E8: =statements!F137 -> 41762.536

Sheet Debt Schedule
A1: LONG TERM DEBT SCHEDULE
A3: Description | B3: 2025 | C3: 2026 | D3: 2027 | E3: 2028 | F3: 2029 | G3: 2030
A4: Beginning Balance | B4: =statements!C29 -> 40000 | C4: =B7 -> 40000 | D4: =C7 -> 40000 | E4: =D7 -> 40000 | F4: =E7 -> 40000 | G4: =F7 -> 40000
A5: Debt Issuance | B5: 0 | C5: 0 | D5: 0 | E5: 0 | F5: 0 | G5: 0
A6: Principal Repayment | B6: 0 | C6: 0 | D6: 0 | E6: 0 | F6: 0 | G6: 0
A7: Ending Balance | B7: =B4+B5-B6 -> 40000 | C7: =C4+C5-C6 -> 40000 | D7: =D4+D5-D6 -> 40000 | E7: =E4+E5-E6 -> 40000 | F7: =F4+F5-F6 -> 40000 | G7: =G4+G5-G6 -> 40000
A9: INTEREST EXPENSE SCHEDULE
A11: Beginning Debt Balance | B11: =B4 -> 40000 | C11: =C4 -> 40000 | D11: =D4 -> 40000 | E11: =E4 -> 40000 | F11: =F4 -> 40000 | G11: =G4 -> 40000
A12: Interest Rate | B12: =statements!D80 -> 0.07 | C12: =statements!D80 -> 0.07 | D12: =statements!D80 -> 0.07 | E12: =statements!D80 -> 0.07 | F12: =statements!D80 -> 0.07 | G12: =statements!D80 -> 0.07
A13: Interest Expense | B13: =B11*B12 -> 2800 | C13: =C11*C12 -> 2800 | D13: =D11*D12 -> 2800 | E13: =E11*E12 -> 2800 | F13: =F11*F12 -> 2800 | G13: =G11*G12 -> 2800
